<?xml version="1.0" ?>
<sdf version="1.5">
  <model name="schunk_mpg_80">
    <link name="base">
      <self_collide>false</self_collide>
      <inertial>
        <pose>0 0.035 0 0 0 0</pose>
        <inertia>
          <ixx>0.00053312</ixx>
          <ixy>0</ixy>
          <ixz>0</ixz>
          <iyy>0.00065312</iyy>
          <iyz>0</iyz>
          <izz>0.000904</izz>
        </inertia>
        <mass>0.96</mass>
      </inertial>
      <visual name="base_geom_visual">
        <pose>0 0 0 0 0 0</pose>
        <geometry>
          <mesh>
            <uri>model://reveal_schunk_description/meshes/mpg_80/visual/SCHUNK_MPG-80_BASE.dae</uri>
          </mesh>
        </geometry>
      </visual>
      <collision name="base_geom_collision">
        <pose>0 0.035 0 0 0 0</pose>
        <geometry>
          <box>
            <size>0.08 0.07 0.042</size>
          </box>
        </geometry>
      </collision>
      <collision name="base_tab1_geom_collision">
        <pose>-0.043 0.036 0.009 0 0 0</pose>
        <geometry>
          <box>
            <size>0.006 0.012 0.012</size>
          </box>
        </geometry>
      </collision>
      <collision name="base_tab2_geom_collision">
        <pose>-0.043 0.036 -0.009 0 0 0</pose>
        <geometry>
          <box>
            <size>0.006 0.012 0.012</size>
          </box>
        </geometry>
      </collision>
    </link>
    <link name="l_finger">
      <self_collide>true</self_collide>
      <inertial>
        <pose>-0.0205 0.0798 0 0 0 0</pose>
        <inertia>
          <ixx>0.0000095236</ixx>
          <ixy>0</ixy>
          <ixz>0</ixz>
          <iyy>0.0000072</iyy>
          <iyz>0</iyz>
          <izz>0.0000052036</izz>
        </inertia>
        <mass>0.12</mass>
      </inertial>
      <visual name="l_finger_geom_visual">
        <pose>0 0 0 0 0 0</pose>
        <geometry>
          <mesh>
            <uri>model://reveal_schunk_description/meshes/mpg_80/visual/SCHUNK_MPG-80_LEFT_FINGER.dae</uri>
          </mesh>
        </geometry>
      </visual>
      <collision name="l_finger_tip_geom_collision">
        <pose>-0.0205 0.0798 0 0 0 0</pose>
        <geometry>
          <box>
            <size>0.012 0.0194 0.024</size>
          </box>
        </geometry>
        <surface>
          <friction>
            <ode>
              <mu>100</mu>
              <mu2>100</mu2>
              <fdir1>0 0 0</fdir1>
              <slip1>0.0</slip1>
              <slip2>0.0</slip2>
            </ode>
            <bullet>
              <friction>100</friction>
              <friction2>100</friction2>
              <fdir1>0 0 0</fdir1>
              <rolling_friction>100</rolling_friction>
            </bullet>
          </friction>
          <contact>
            <ode>
              <soft_cfm>0</soft_cfm>
              <soft_erp>0.2</soft_erp>
              <kp>1e12</kp>
              <kd>1e8</kd>
              <max_vel>0.01</max_vel>
              <min_depth>0.002</min_depth>
            </ode>
            <bullet>
              <soft_cfm>0</soft_cfm>
              <soft_erp>0.2</soft_erp>
              <kp>1e12</kp>
              <kd>1.0</kd>
              <split_impulse>1</split_impulse>
              <split_impulse_penetration_threshold>-0.01</split_impulse_penetration_threshold>
            </bullet>
          </contact>
        </surface>
      </collision>
    </link>
    <link name="r_finger">
      <self_collide>true</self_collide>
      <inertial>
        <pose>0.0205 0.0798 0 0 0 0</pose>
        <inertia>
          <ixx>0.0000095236</ixx>
          <ixy>0</ixy>
          <ixz>0</ixz>
          <iyy>0.0000072</iyy>
          <iyz>0</iyz>
          <izz>0.0000052036</izz>
        </inertia>
        <mass>0.12</mass>
      </inertial>
      <visual name="r_finger_geom_visual">
        <pose>0 0 0 0 0 0</pose>
        <geometry>
          <mesh>
            <uri>model://reveal_schunk_description/meshes/mpg_80/visual/SCHUNK_MPG-80_RIGHT_FINGER.dae</uri>
          </mesh>
        </geometry>
      </visual>
      <collision name="r_finger_tip_geom_collision">
        <pose>0.0205 0.0798 0 0 0 0</pose>
        <geometry>
          <box>
            <size>0.012 0.0194 0.024</size>
          </box>
        </geometry>
        <surface>
          <friction>
            <ode>
              <mu>100</mu>
              <mu2>100</mu2>
              <fdir1>0 0 0</fdir1>
              <slip1>0.0</slip1>
              <slip2>0.0</slip2>
            </ode>
            <bullet>
              <friction>100</friction>
              <friction2>100</friction2>
              <fdir1>0 0 0</fdir1>
              <rolling_friction>100</rolling_friction>
            </bullet>
          </friction>
          <contact>
            <ode>
              <soft_cfm>0</soft_cfm>
              <soft_erp>0.2</soft_erp>
              <kp>1e12</kp>
              <kd>1e8</kd>
              <max_vel>0.01</max_vel>
              <min_depth>0.002</min_depth>
            </ode>
            <bullet>
              <soft_cfm>0</soft_cfm>
              <soft_erp>0.2</soft_erp>
              <kp>1e12</kp>
              <kd>1.0</kd>
              <split_impulse>1</split_impulse>
              <split_impulse_penetration_threshold>-0.01</split_impulse_penetration_threshold>
            </bullet>
          </contact>
        </surface>
      </collision>
    </link>

    <joint name="l_finger_actuator" type="prismatic"> 
      <parent>base</parent>
      <child>l_finger</child>
      <axis>
        <dynamics>
          <damping>0.0</damping>
          <friction>0.0</friction>
        </dynamics>
        <xyz>1 0 0</xyz>
        <limit>
          <lower>0</lower>
          <upper>0.014</upper>
        </limit>
      </axis>
    </joint>

    <joint name="r_finger_actuator" type="prismatic"> 
      <parent>base</parent>
      <child>r_finger</child>
      <axis>
        <dynamics>
          <damping>0.0</damping>
          <friction>0.0</friction>
        </dynamics>
        <xyz>1 0 0</xyz>
        <limit>
          <lower>-0.014</lower>
          <upper>0</upper>
        </limit>
      </axis>
    </joint>
  </model>
</sdf>
