<?xml version="1.0" ?>
<sdf version='1.5'>
  <model name='pendulum'>
    <link name='base_link'>
      <visual name='base_link_visual'>
        <pose>0 0 0 0 0 0</pose>
        <geometry>
          <sphere>
            <radius>0.05</radius>
          </sphere>
        </geometry>
      </visual>
    </link>
    <link name='arm_link'>
      <pose>0 0 0 0 0 0</pose>
      <visual name='arm_link_visual'>
        <pose>0 0 -0.5 0 0 0</pose>
        <geometry>
          <cylinder>
            <radius>0.025</radius>
            <length>1.0</length>
          </cylinder>
        </geometry>
      </visual>
    </link>
    <joint name='pivot_joint' type='revolute'>
      <child>arm_link</child>
      <parent>base_link</parent>
      <axis>
        <xyz>1 0 0</xyz>
        <limit>
          <lower>-6.28319</lower>
          <upper>6.28319</upper>
        </limit>
        <use_parent_model_frame>1</use_parent_model_frame>
      </axis>
    </joint>
    <link name='bob_link'>
      <pose>0 0 -1.0 0 0 0</pose>
      <inertial>
        <pose>0 0 0 0 0 0</pose>
        <mass>0.1</mass>
        <inertia>
          <ixx>0.0004</ixx>
          <ixy>0</ixy>
          <ixz>0</ixz>
          <iyy>0.0004</iyy>
          <iyz>0</iyz>
          <izz>0.0004</izz>
        </inertia>
      </inertial>
      <visual name='bob_link_visual'>
        <pose>0 0 0 0 0 0</pose>
        <geometry>
          <sphere>
            <radius>0.1</radius>
          </sphere>
        </geometry>
      </visual>
    </link>
    <joint name='arm_bob_weld' type='revolute'>
      <child>bob_link</child>
      <parent>arm_link</parent>
      <axis>
        <xyz>0 1 0</xyz>
        <limit>
          <lower>0</lower>
          <upper>0</upper>
        </limit>
        <use_parent_model_frame>1</use_parent_model_frame>
      </axis>
    </joint>
    <joint name='world_base_weld' type='revolute'>
      <child>base_link</child> 
      <parent>world</parent>
      <axis>
        <xyz>0 0 1</xyz>
        <limit>
          <lower>0</lower>
          <upper>0</upper>
        </limit>
      </axis>
    </joint>
  </model>
</sdf>
